Workbook
Name Agency: #REF!
Name Agency_Name: #REF!
Name Bureau_Code: #REF!
Name EST: #REF!
Name TOTAL_RWA_COST: #REF!

Sheet TICS 
B1: TENANT IMPROVEMENTS COST SUMMARY (TICS) | E1: Version Oct. 2024
B2: For: | C2: =IF(INPUT!$C$3=0,"-",INPUT!$C$3) -> RLP # 36C248-25-R-0110 – EXHIBIT K | D2: ABOA SF= | E2: =INPUT!C7 -> 0
B3: Agency: | C3: =IF(INPUT!$C$4=0,"-",INPUT!$C$4) -> US Department of Veterans Affairs | D3: TIA PER ABOA SF= | E3: =+INPUT!$C$8 -> 0
A4: =IF(INPUT!$C$10=0,"",INPUT!$C$10) | B4: Location: | C4: =IF(INPUT!$C$5=0,"-",INPUT!$C$5) -> Ceiba, Puerto Rico | D4: TOTAL TIA= | E4: =E2*E3 -> 0
B6: Common Area Factor: | C6: =IF(INPUT!C7=0,"-",(INPUT!C9-INPUT!C7)/INPUT!C7) -> - | D6: RSF= | E6: =INPUT!C9 -> 0
A7: Masterformat CSI | B7: System Elements | D7: TI* | E7: SHELL**
A8: Div 1 | B8: General Requirements | D8: ='1'!I20 -> 0 | E8: ='1'!I38 -> 0
A9: Div 2 | B9: Existing Conditions | D9: ='2'!I21 -> 0 | E9: ='2'!I39 -> 0
A10: Div 3 | B10: Concrete | D10: ='3'!I20 -> 0 | E10: ='3'!I38 -> 0
A11: Div 4 | B11: Masonry | D11: ='4'!I20 -> 0 | E11: ='4'!I38 -> 0
A12: Div 5 | B12: Metals | D12: ='5'!I20 -> 0 | E12: ='5'!I38 -> 0
A13: Div 6 | B13: Wood, Plastics, Composites | D13: ='6'!I20 -> 0 | E13: ='6'!I38 -> 0
A14: Div 7 | B14: Thermal and Moisture Protection | D14: ='7'!I20 -> 0 | E14: ='7'!I38 -> 0
A15: Div 8 | B15: Openings | D15: ='8'!I32 -> 0 | E15: ='8'!I60 -> 0
A16: Div 9 | B16: Finishes | D16: ='9'!I32 -> 0 | E16: ='9'!I60 -> 0
A17: Div 10 | B17: Specialties | D17: ='10'!I20 -> 0 | E17: ='10'!I38 -> 0
A18: Div 11 | B18: Equipment | D18: ='11'!I20 -> 0 | E18: ='11'!I38 -> 0
A19: Div 12 | B19: Furnishings | D19: ='12'!I32 -> 0 | E19: ='12'!I50 -> 0
A20: Div 13 | B20: Special Construction | D20: ='13'!I20 -> 0 | E20: ='13'!I38 -> 0
A21: Div 14 | B21: Conveying Equipment | D21: ='14'!I20 -> 0 | E21: ='14'!I38 -> 0
A22: Div 21 | B22: Fire Suppression | D22: ='21'!I20 -> 0 | E22: ='21'!I38 -> 0
A23: Div 22 | B23: Plumbing | D23: ='22'!I32 -> 0 | E23: ='22'!I50 -> 0
A24: Div 23 | B24: Heating, Ventilating, and Air Conditioning (HVAC) | D24: ='23'!I32 -> 0 | E24: ='23'!I50 -> 0
A25: Div 26.1 | B25: Electrical | D25: ='26.1'!I32 -> 0 | E25: ='26.1'!I50 -> 0
A26: Div 26.2 | B26: Lighting | D26: ='26.2'!I32 -> 0 | E26: ='26.2'!I50 -> 0
A27: Div 27 | B27: Communications | D27: ='27'!I32 -> 0 | E27: ='27'!I50 -> 0
A28: Div 28.1 | B28: Electronic Safety | D28: ='28.1'!I32 -> 0 | E28: ='28.1'!I50 -> 0
A29: Div 28.2 | B29: Electronic Security (TI - Non-BSAC) | D29: ='28.2'!I32 -> 0 | E29: ='28.2'!I50 -> 0
A30: Div 31 | B30: Earthwork | D30: ='31'!I20 -> 0 | E30: ='31'!I38 -> 0
A31: Div 32 | B31: Exterior Improvements | D31: ='32'!I20 -> 0 | E31: ='32'!I38 -> 0
A32: Div 33 | B32: Utilities | D32: ='33'!I20 -> 0 | E32: ='33'!I38 -> 0
A33: Subtotal | B33: Trade Costs | D33: =SUM(D8:D32) -> 0 | E33: =SUM(E8:E32) -> 0
B34: General Contractor Fee | C34: =IF(INPUT!$C$12 = "lump sum","Lump Sum",IF(INPUT!$C$12 = "percent","Percent","")) -> Percent | D34: =IF(INPUT!C12="lump sum",INPUT!D12,IF(INPUT!C12="percent",INPUT!D12*D33,0)) -> 0 | E34: =IF(INPUT!C13="lump sum",INPUT!D13,IF(INPUT!C13="percent",INPUT!D13*E33,0)) -> 0
A35: Subtotal | B35: Construction Costs | D35: =D33+D34 -> 0 | E35: =E33+E34 -> 0
B36: Architectural & Engineering Fees (NIC DID costs) *** | C36: =IF(INPUT!$C$14 = "lump sum","Lump Sum",IF(INPUT!$C$14="percent","Percent","")) -> Percent | D36: =IF(INPUT!C14="lump sum",INPUT!D14,IF(INPUT!C14="percent",D35*INPUT!D14,0)) -> 0 | E36: =IF(INPUT!C15="lump sum",INPUT!D15,IF(INPUT!C15="percent",E35*INPUT!D15,0)) -> 0
B37: Other Lessor Costs Established Under the Lease | D37: =INPUT!$C$18 -> 0 | E37: =INPUT!$D$18 -> 0
A38: Subtotal | B38: Lessor's Costs: | D38: =SUM(D35:D37) -> 0 | E38: =SUM(E35:E37) -> 0
B39: Lessor's Project Management Fee | C39: =IF(INPUT!$C$16 = "percent","Percent","") -> Percent | D39: =IF(INPUT!C16="lump sum",INPUT!$D$16,IF(INPUT!C16="percent",INPUT!$D$16*D35,0)) -> 0
A40: Total | B40: Price to Government: | C40: GRAND TOTAL | D40: =D38+D39 -> 0
C41: Cost per ABOA SF | D41: =IF(E2=0,0,(D40/E2)) -> 0 | E41: =IF(E2=0,0,(E38/E2)) -> 0
...

Sheet INSTRUCTIONS
A1: INSTRUCTIONS
B2: Read and understand 'SHELL' tab.
B3: Input project specific information as appropriate in the light blue fields of the 'INPUT' worksheet, in order to auto-populate the TICS worksheet. This includes ANSI-BOMA Office Area (ABOA) square footage, General Contractor Fee, Lessor's Project Management Fee, and A/E Fees. Note that some of these fees are already established under the lease agreement and must be used when completing this worksheet.
B4: Fill in each line for all Shell and TI items in the corresponding division tabs included in the Tenant Improvement Cost Summary (TICS). Include all subcontractors' soft costs. Example shown below.
A5: Material
A6: Description | C6: Accurately describe each item being priced.
A7: Quantity | C7: List the quantity e.g., 1, 2, 3, etc.
A8: Unit | C8: (Example) LS,EA,GAL,LF, SF, etc.
A9: Cost | C9: Amount per one unit
A10: Total | C10: Total cost of all material.
A11: Labor
A12: Hours | C12: Time projected to perform the task.
A13: Labor Rate | C13: Cost per hour of labor.
A14: Total | C14: Cost of labor.
A15: TOTAL Combines overall materials and labor.
A17: Tenant Improvements (TI)
A19: TIs include the finishes and fixtures that take space from the shell condition to a finished, usable condition.
A21: 1. | B21: Fill out light blue fields categorized Tenant Improvements (TI), inputting only costs associated with TI.
A23: 2. | B23: Fill each division tab 1-33 as needed for the construction to be performed under the TI costs as indicated above.
A27: Shell
A29: 1. | B29: Fill out light blue fields categorized SHELL, inputting only costs associated with shell as defined in the 'SHELL' tab.
A32: 2. | B32: Fill each division tab 1-33 as needed for the construction to be preformed under the SHELL cost as indicated above.
A35: DIVISION 9 - FINISHES | G35: FOR: | I35: DATE PREPARED:
G36: Project or Lease # | I36: 44562
A37: Tentant Improvement (TI) Cost Estimate for Division 9
C38: MATERIAL | G38: LABOR
A39: DESCRIPTION | C39: QUAN. | D39: UNIT | E39: COST | F39: TOTAL | G39: HOURS | H39: Labor Rate | I39: TOTAL
A40: XYZ Paint | C40: 1 | D40: GAL. | E40: 25 | F40: =C40*E40 -> 25 | G40: 2.5 | H40: 36.25 | I40: =G40*H40 -> 90.625
F41: =C41*E41 -> 0 | I41: =G41*H41 -> 0
F42: =C42*E42 -> 0 | I42: =G42*H42 -> 0
E43: Material Total: | F43: =SUM(F40:F42) -> 25 | H43: Labor Total: | I43: =SUM(I40:I42) -> 90.625
H44: TOTAL TI MATERIAL & LABOR: | I44: =SUM(F43+I43) -> 115.625
A45: Shell Cost Estimate for Division 9
C46: MATERIAL | G46: LABOR
A47: DESCRIPTION | C47: QUAN. | D47: UNIT | E47: COST | F47: TOTAL | G47: HOURS | H47: Labor Rate | I47: TOTAL
A48: ABC Paint | C48: 10 | D48: GAL. | E48: 27 | F48: =C48*E48 -> 270 | G48: 6 | H48: 36.25 | I48: =G48*H48 -> 217.5
F49: =C49*E49 -> 0 | I49: =G49*H49 -> 0
F50: =C50*E50 -> 0 | I50: =G50*H50 -> 0
E51: Material Total: | F51: =SUM(F48:F50) -> 270 | H51: Labor Total: | I51: =SUM(I48:I50) -> 217.5
H52: TOTAL SHELL MATERIAL & LABOR: | I52: =SUM(F51+I51) -> 487.5
...

Sheet SHELL
B1: Per GSA Pricing Desk Guide, 5th Edition.
B2: Table 2-4. Shell Definition for General Use Buildings
B3: Base Building | C3: Occupant Areas
B4: Base structure and building enclosure components (windows with exterior finishes) are complete. | C4: Broom-clean concrete floor slab, with a flat and level floor.
B5: Base building mechanical, electrical and plumbing systems (e.g., central fire alarm, chiller plant, cooling tower) are complete and functional. | C5: Gypsum wallboard, spackled and prime painted, on exterior perimeter walls and tenant demising walls, without suite entry door.
B6: All common areas, such as lobbies, elevators, fire egress corridors and stairwells, garages, and service areas are complete. (Circulation corridors are provided as part of the base building only on multi- tenanted floors where the corridor is common to more than one tenant. On single tenant floors, only the fire egress corridor necessary to meet code is provided as part of the shell.) | C6: Suspended acoustical ceiling system including grid and lay-in tiles (or other building standard). Lighting luminaires should be installed in the ceiling grid for an open office plan at the rate of one fixture per 80 USF.3 Lighting controls with ambient lighting adjusted per daylight availability, occupancy, vacancy, or other building automation system signals.
B7: Building common restrooms are complete and operational.
B8: Building cores on each floor with assignable space contain the following: tappable domestic water riser, service sanitary drain, sanitary vent, ready for extension to tenant- demised areas. Electrical power distribution panels and circuit breakers available in an electrical closet, with capacity at 120/208 volt, 3- phase, 4-wire providing 4 watts per USF excluding lighting and HVAC. Designated connection point to the central fire alarm system for extension to tenant- demised areas. Distribution backboard within a wire closet for connection to tenant’s telephone lines. Vertical conduit (empty sleeve) through building core, available for tenant wiring and cabling. | C8: Central heating, ventilation, and air conditioning (HVAC) systems are installed and operational, including, as appropriate, main and branch lines, variable air volume boxes, dampers, flex ducts and diffusers, for open office layout. Conditioned air through medium pressure ductwork at a rate of .75 cfm per square foot of usable area is provided. Sprinkler mains and distribution piping in a protection layout (open plan) with heads turned down, concealed with an escutcheon or trim plate, are installed.

Sheet INPUT
B1: INFORMATION NEEDED TO COMPLETE TICS TABLE | E1: =C12="lump sum" -> FALSE
E2: =C14="lump sum" -> FALSE
B3: LEASE GS-XXP-LXXXXXXX or Project | C3: RLP # 36C248-25-R-0110 – EXHIBIT K | E3: =IF(C13="lump sum",TRUE,FALSE) -> FALSE
B4: Agency | C4: US Department of Veterans Affairs | E4: =IF(C14="lump sum",TRUE,FALSE) -> FALSE
B5: Location: City, State | C5: Ceiba, Puerto Rico | E5: =IF(C15="lump sum",TRUE,FALSE) -> FALSE
E6: =C16="lump sum" -> FALSE
B7: ABOA SF = | I7: General contractor fee, A/E Fee and Lessor's Project Management Fee fields are structured to allow you to choose percentage or a lump sum.
B8: TENANT IMPROVEMENT ALLOWANCE PER ABOA SF =
B9: RSF=
B10: DATE:
C11: Basis | D11: Amount
B12: Tenant Improvement General Contractor Fee | C12: percent | I12: Enter percent values as decimals. Ex: 0.06 for 6.00%
B13: Shell General Contractor Fee | C13: percent
B14: Tenant Improvement A/E Fees (per Lease) | C14: percent
B15: Shell A/E Fees | C15: percent | I15: For A/E fees established as a cost per ABOA sf, convert rate to lump sum.
B16: Lessor's TI Project Management Fee (per Lease) | C16: percent | H16: percent
C17: TI | D17: Shell | H17: lump sum
B18: Other Lessor Costs Established Under the Lease
B20: If BSAC is applicable, 'Amount' values entered above for TI fees that have a 'percent' basis will automatically be applied to BSAC on the TICS tab. 'Lump Sum' basis amounts will NOT be applied twice; 'lump sum' basis amounts entered above should consider the full scope of both TI and BSAC and will only be displayed once on the TICS tab.

Sheet BSAC
A1: BUILDING SPECIFIC AMORTIZED CAPITAL (BSAC) | G1: FOR: | I1: DATE PREPARED:
G2: =IF(INPUT!C3=0,"",INPUT!C3) -> RLP # 36C248-25-R-0110 – EXHIBIT K | I2: =IF(INPUT!C10=0,"",INPUT!C10)
A3: Building Specific Amortized Capital (BSAC) Cost Estimate (Most commonly itemized on a Security Unit Price List.)
A4: Select Method of BSAC Inclusion: | F4: N/A | H4: ← Click if entering BSAC values
A5: =IF(F4="Direct Input from Security Unit Price List","Enter the Total Costs from the Security Unit Price List in F5 →",IF(F4="Itemized Costs","Do not enter a value in F5. Itemize costs below instead.","If entering BSAC values, select method from cell F4 dropdown list.")) -> If entering BSAC values, select method from cell F4 dropdown list.
A7: DESCRIPTION | C7: MATERIAL | G7: LABOR
C8: QUANTITY | D8: UNIT | E8: COST | F8: TOTAL | G8: HOURS | H8: Labor Rate | I8: TOTAL
A9: Describe first item here | C9: 1 | D9: (ex: LF) | E9: 0 | F9: =C9*E9 -> 0 | G9: 1 | H9: 0 | I9: =G9*H9 -> 0
F10: =C10*E10 -> 0 | I10: =G10*H10 -> 0
F11: =C11*E11 -> 0 | I11: =G11*H11 -> 0
F12: =C12*E12 -> 0 | I12: =G12*H12 -> 0
F13: =C13*E13 -> 0 | I13: =G13*H13 -> 0
F14: =C14*E14 -> 0 | I14: =G14*H14 -> 0
F15: =C15*E15 -> 0 | I15: =G15*H15 -> 0
F16: =C16*E16 -> 0 | I16: =G16*H16 -> 0
F17: =C17*E17 -> 0 | I17: =G17*H17 -> 0
F18: =C18*E18 -> 0 | I18: =G18*H18 -> 0
F19: =C19*E19 -> 0 | I19: =G19*H19 -> 0
F20: =C20*E20 -> 0 | I20: =G20*H20 -> 0
F21: =C21*E21 -> 0 | I21: =G21*H21 -> 0
C22: MATERIAL TOTAL: | F22: =SUM(F9:F21) -> 0 | G22: LABOR TOTAL: | I22: =SUM(I9:I21) -> 0
A23: TOTAL BSAC MATERIAL AND LABOR: | I23: =SUM(I22,F22) -> 0

Sheet 1
A1: Division 1 - General Requirements | G1: FOR: | I1: DATE PREPARED:
G2: =IF(INPUT!C3=0,"",INPUT!C3) -> RLP # 36C248-25-R-0110 – EXHIBIT K | I2: =IF(INPUT!C10=0,"",INPUT!C10)
A3: Tentant Improvement (TI) Cost Estimate for Division 1 (examples: superintendence, mob/demob, dust control, waste & dumpsters, temporary barriers & barricades)
A4: DESCRIPTION | C4: MATERIAL | G4: LABOR
C5: QUANTITY | D5: UNIT | E5: COST | F5: TOTAL | G5: HOURS | H5: Labor Rate | I5: TOTAL
A6: Describe first item here | C6: 1 | D6: (ex: LF) | E6: 0 | F6: =C6*E6 -> 0 | G6: 1 | H6: 0 | I6: =G6*H6 -> 0
F7: =C7*E7 -> 0 | I7: =G7*H7 -> 0
F8: =C8*E8 -> 0 | I8: =G8*H8 -> 0
F9: =C9*E9 -> 0 | I9: =G9*H9 -> 0
F10: =C10*E10 -> 0 | I10: =G10*H10 -> 0
F11: =C11*E11 -> 0 | I11: =G11*H11 -> 0
F12: =C12*E12 -> 0 | I12: =G12*H12 -> 0
F13: =C13*E13 -> 0 | I13: =G13*H13 -> 0
F14: =C14*E14 -> 0 | I14: =G14*H14 -> 0
F15: =C15*E15 -> 0 | I15: =G15*H15 -> 0
F16: =C16*E16 -> 0 | I16: =G16*H16 -> 0
F17: =C17*E17 -> 0 | I17: =G17*H17 -> 0
F18: =C18*E18 -> 0 | I18: =G18*H18 -> 0
C19: MATERIAL TOTAL: | F19: =SUM(F6:F18) -> 0 | G19: LABOR TOTAL: | I19: =SUM(I6:I18) -> 0
A20: TOTAL TI MATERIAL AND LABOR: | I20: =SUM(I19,F19) -> 0
A21: SHELL Cost Estimate for Division 1 (examples: superintendence, mob/demob, dust control, waste & dumpsters, temporary barriers & barricades)
A22: DESCRIPTION | C22: MATERIAL | G22: LABOR
C23: QUANTITY | D23: UNIT | E23: COST | F23: TOTAL | G23: HOURS | H23: Labor Rate | I23: TOTAL
C24: 1 | E24: 0 | F24: =C24*E24 -> 0 | G24: 1 | H24: 0 | I24: =G24*H24 -> 0
F25: =C25*E25 -> 0 | I25: =G25*H25 -> 0
F26: =C26*E26 -> 0 | I26: =G26*H26 -> 0
F27: =C27*E27 -> 0 | I27: =G27*H27 -> 0
F28: =C28*E28 -> 0 | I28: =G28*H28 -> 0
F29: =C29*E29 -> 0 | I29: =G29*H29 -> 0
F30: =C30*E30 -> 0 | I30: =G30*H30 -> 0
F31: =C31*E31 -> 0 | I31: =G31*H31 -> 0
F32: =C32*E32 -> 0 | I32: =G32*H32 -> 0
F33: =C33*E33 -> 0 | I33: =G33*H33 -> 0
F34: =C34*E34 -> 0 | I34: =G34*H34 -> 0
F35: =C35*E35 -> 0 | I35: =G35*H35 -> 0
F36: =C36*E36 -> 0 | I36: =G36*H36 -> 0
C37: MATERIAL TOTAL: | F37: =SUM(F24:F36) -> 0 | G37: LABOR TOTAL: | I37: =SUM(I24:I36) -> 0
A38: TOTAL SHELL MATERIAL AND LABOR: | I38: =SUM(I37,F37) -> 0

Sheet 2
A1: Division 2 - Existing Conditions | G1: FOR: | I1: DATE PREPARED:
G2: =IF(INPUT!C3=0,"",INPUT!C3) -> RLP # 36C248-25-R-0110 – EXHIBIT K | I2: =IF(INPUT!C10=0,"",INPUT!C10)
A3: Tentant Improvement (TI) Cost Estimate for Division 2 (examples: site work, demolition)
A4: DESCRIPTION | C4: MATERIAL | G4: LABOR
C5: QUANTITY | D5: UNIT | E5: COST | F5: TOTAL | G5: HOURS | H5: Labor Rate | I5: TOTAL
A6: Describe first item here | C6: 1 | D6: (ex: LF) | E6: 0 | F6: =C6*E6 -> 0 | G6: 1 | H6: 0 | I6: =G6*H6 -> 0
F7: =C7*E7 -> 0 | I7: =G7*H7 -> 0
F8: =C8*E8 -> 0 | I8: =G8*H8 -> 0
F9: =C9*E9 -> 0 | I9: =G9*H9 -> 0
F10: =C10*E10 -> 0 | I10: =G10*H10 -> 0
F11: =C11*E11 -> 0 | I11: =G11*H11 -> 0
F12: =C12*E12 -> 0 | I12: =G12*H12 -> 0
F13: =C13*E13 -> 0 | I13: =G13*H13 -> 0
F14: =C14*E14 -> 0 | I14: =G14*H14 -> 0
F15: =C15*E15 -> 0 | I15: =G15*H15 -> 0
F16: =C16*E16 -> 0 | I16: =G16*H16 -> 0
F17: =C17*E17 -> 0 | I17: =G17*H17 -> 0
F18: =C18*E18 -> 0 | I18: =G18*H18 -> 0
F19: =C19*E19 -> 0 | I19: =G19*H19 -> 0
C20: MATERIAL TOTAL: | F20: =SUM(F6:F19) -> 0 | G20: LABOR TOTAL: | I20: =SUM(I6:I19) -> 0
A21: TOTAL TI MATERIAL AND LABOR: | I21: =SUM(I20,F20) -> 0
A22: SHELL Cost Estimate for Division 2 (examples: demolition, survey, geotech, HAZMAT)
A23: DESCRIPTION | C23: MATERIAL | G23: LABOR
C24: QUANTITY | D24: UNIT | E24: COST | F24: TOTAL | G24: HOURS | H24: Labor Rate | I24: TOTAL
C25: 1 | E25: 0 | F25: =C25*E25 -> 0 | G25: 1 | H25: 0 | I25: =G25*H25 -> 0
F26: =C26*E26 -> 0 | I26: =G26*H26 -> 0
F27: =C27*E27 -> 0 | I27: =G27*H27 -> 0
F28: =C28*E28 -> 0 | I28: =G28*H28 -> 0
F29: =C29*E29 -> 0 | I29: =G29*H29 -> 0
F30: =C30*E30 -> 0 | I30: =G30*H30 -> 0
F31: =C31*E31 -> 0 | I31: =G31*H31 -> 0
F32: =C32*E32 -> 0 | I32: =G32*H32 -> 0
F33: =C33*E33 -> 0 | I33: =G33*H33 -> 0
F34: =C34*E34 -> 0 | I34: =G34*H34 -> 0
F35: =C35*E35 -> 0 | I35: =G35*H35 -> 0
F36: =C36*E36 -> 0 | I36: =G36*H36 -> 0
F37: =C37*E37 -> 0 | I37: =G37*H37 -> 0
C38: MATERIAL TOTAL: | F38: =SUM(F25:F37) -> 0 | G38: LABOR TOTAL: | I38: =SUM(I25:I37) -> 0
A39: TOTAL SHELL MATERIAL AND LABOR: | I39: =SUM(I38,F38) -> 0

Sheet 3
A1: Division 3 - Concrete | G1: FOR: | I1: DATE PREPARED:
G2: =IF(INPUT!C3=0,"",INPUT!C3) -> RLP # 36C248-25-R-0110 – EXHIBIT K | I2: =IF(INPUT!C10=0,"",INPUT!C10)
A3: Tentant Improvement (TI) Cost Estimate for Division 3
A4: DESCRIPTION | C4: MATERIAL | G4: LABOR
C5: QUANTITY | D5: UNIT | E5: COST | F5: TOTAL | G5: HOURS | H5: Labor Rate | I5: TOTAL
A6: Describe first item here | C6: 1 | D6: (ex: LF) | E6: 0 | F6: =C6*E6 -> 0 | G6: 1 | H6: 0 | I6: =G6*H6 -> 0
F7: =C7*E7 -> 0 | I7: =G7*H7 -> 0
F8: =C8*E8 -> 0 | I8: =G8*H8 -> 0
F9: =C9*E9 -> 0 | I9: =G9*H9 -> 0
F10: =C10*E10 -> 0 | I10: =G10*H10 -> 0
F11: =C11*E11 -> 0 | I11: =G11*H11 -> 0
F12: =C12*E12 -> 0 | I12: =G12*H12 -> 0
F13: =C13*E13 -> 0 | I13: =G13*H13 -> 0
F14: =C14*E14 -> 0 | I14: =G14*H14 -> 0
F15: =C15*E15 -> 0 | I15: =G15*H15 -> 0
F16: =C16*E16 -> 0 | I16: =G16*H16 -> 0
F17: =C17*E17 -> 0 | I17: =G17*H17 -> 0
F18: =C18*E18 -> 0 | I18: =G18*H18 -> 0
C19: MATERIAL TOTAL: | F19: =SUM(F6:F18) -> 0 | G19: LABOR TOTAL: | I19: =SUM(I6:I18) -> 0
A20: TOTAL TI MATERIAL AND LABOR: | I20: =SUM(I19,F19) -> 0
A21: SHELL Cost Estimate for Division 3 (examples: foundations, columns, flatwork, beams)
A22: DESCRIPTION | C22: MATERIAL | G22: LABOR
C23: QUANTITY | D23: UNIT | E23: COST | F23: TOTAL | G23: HOURS | H23: Labor Rate | I23: TOTAL
C24: 1 | E24: 0 | F24: =C24*E24 -> 0 | G24: 1 | H24: 0 | I24: =G24*H24 -> 0
F25: =C25*E25 -> 0 | I25: =G25*H25 -> 0
F26: =C26*E26 -> 0 | I26: =G26*H26 -> 0
F27: =C27*E27 -> 0 | I27: =G27*H27 -> 0
F28: =C28*E28 -> 0 | I28: =G28*H28 -> 0
F29: =C29*E29 -> 0 | I29: =G29*H29 -> 0
F30: =C30*E30 -> 0 | I30: =G30*H30 -> 0
F31: =C31*E31 -> 0 | I31: =G31*H31 -> 0
F32: =C32*E32 -> 0 | I32: =G32*H32 -> 0
F33: =C33*E33 -> 0 | I33: =G33*H33 -> 0
F34: =C34*E34 -> 0 | I34: =G34*H34 -> 0
F35: =C35*E35 -> 0 | I35: =G35*H35 -> 0
F36: =C36*E36 -> 0 | I36: =G36*H36 -> 0
C37: MATERIAL TOTAL: | F37: =SUM(F24:F36) -> 0 | G37: LABOR TOTAL: | I37: =SUM(I24:I36) -> 0
A38: TOTAL SHELL MATERIAL AND LABOR: | I38: =SUM(I37,F37) -> 0

Sheet 4
A1: Division 4 - Masonry | G1: FOR: | I1: DATE PREPARED:
G2: =IF(INPUT!C3=0,"",INPUT!C3) -> RLP # 36C248-25-R-0110 – EXHIBIT K | I2: =IF(INPUT!C10=0,"",INPUT!C10)
A3: Tentant Improvement (TI) Cost Estimate for Division 4
A4: DESCRIPTION | C4: MATERIAL | G4: LABOR
C5: QUANTITY | D5: UNIT | E5: COST | F5: TOTAL | G5: HOURS | H5: Labor Rate | I5: TOTAL
A6: Describe first item here | C6: 1 | D6: (ex: LF) | E6: 0 | F6: =C6*E6 -> 0 | G6: 1 | H6: 0 | I6: =G6*H6 -> 0
F7: =C7*E7 -> 0 | I7: =G7*H7 -> 0
F8: =C8*E8 -> 0 | I8: =G8*H8 -> 0
F9: =C9*E9 -> 0 | I9: =G9*H9 -> 0
F10: =C10*E10 -> 0 | I10: =G10*H10 -> 0
F11: =C11*E11 -> 0 | I11: =G11*H11 -> 0
F12: =C12*E12 -> 0 | I12: =G12*H12 -> 0
F13: =C13*E13 -> 0 | I13: =G13*H13 -> 0
F14: =C14*E14 -> 0 | I14: =G14*H14 -> 0
F15: =C15*E15 -> 0 | I15: =G15*H15 -> 0
F16: =C16*E16 -> 0 | I16: =G16*H16 -> 0
F17: =C17*E17 -> 0 | I17: =G17*H17 -> 0
F18: =C18*E18 -> 0 | I18: =G18*H18 -> 0
C19: MATERIAL TOTAL: | F19: =SUM(F6:F18) -> 0 | G19: LABOR TOTAL: | I19: =SUM(I6:I18) -> 0
A20: TOTAL TI MATERIAL AND LABOR: | I20: =SUM(I19,F19) -> 0
A21: SHELL Cost Estimate for Division 4 (examples: brick, block)
A22: DESCRIPTION | C22: MATERIAL | G22: LABOR
C23: QUANTITY | D23: UNIT | E23: COST | F23: TOTAL | G23: HOURS | H23: Labor Rate | I23: TOTAL
C24: 1 | E24: 0 | F24: =C24*E24 -> 0 | G24: 1 | H24: 0 | I24: =G24*H24 -> 0
F25: =C25*E25 -> 0 | I25: =G25*H25 -> 0
F26: =C26*E26 -> 0 | I26: =G26*H26 -> 0
F27: =C27*E27 -> 0 | I27: =G27*H27 -> 0
F28: =C28*E28 -> 0 | I28: =G28*H28 -> 0
F29: =C29*E29 -> 0 | I29: =G29*H29 -> 0
F30: =C30*E30 -> 0 | I30: =G30*H30 -> 0
F31: =C31*E31 -> 0 | I31: =G31*H31 -> 0
F32: =C32*E32 -> 0 | I32: =G32*H32 -> 0
F33: =C33*E33 -> 0 | I33: =G33*H33 -> 0
F34: =C34*E34 -> 0 | I34: =G34*H34 -> 0
F35: =C35*E35 -> 0 | I35: =G35*H35 -> 0
F36: =C36*E36 -> 0 | I36: =G36*H36 -> 0
C37: MATERIAL TOTAL: | F37: =SUM(F24:F36) -> 0 | G37: LABOR TOTAL: | I37: =SUM(I24:I36) -> 0
A38: TOTAL SHELL MATERIAL AND LABOR: | I38: =SUM(I37,F37) -> 0

Sheet 5
A1: Division 5 - Metals | G1: FOR: | I1: DATE PREPARED:
G2: =IF(INPUT!C3=0,"",INPUT!C3) -> RLP # 36C248-25-R-0110 – EXHIBIT K | I2: =IF(INPUT!C10=0,"",INPUT!C10)
A3: Tentant Improvement (TI) Cost Estimate for Division 5 (examples: structural, grates, decking, joists, stairs, railings, custom fabrications)
A4: DESCRIPTION | C4: MATERIAL | G4: LABOR
C5: QUANTITY | D5: UNIT | E5: COST | F5: TOTAL | G5: HOURS | H5: Labor Rate | I5: TOTAL
A6: Describe first item here | C6: 1 | D6: (ex: LF) | E6: 0 | F6: =C6*E6 -> 0 | G6: 1 | H6: 0 | I6: =G6*H6 -> 0
F7: =C7*E7 -> 0 | I7: =G7*H7 -> 0
F8: =C8*E8 -> 0 | I8: =G8*H8 -> 0
F9: =C9*E9 -> 0 | I9: =G9*H9 -> 0
F10: =C10*E10 -> 0 | I10: =G10*H10 -> 0
F11: =C11*E11 -> 0 | I11: =G11*H11 -> 0
F12: =C12*E12 -> 0 | I12: =G12*H12 -> 0
F13: =C13*E13 -> 0 | I13: =G13*H13 -> 0
F14: =C14*E14 -> 0 | I14: =G14*H14 -> 0
F15: =C15*E15 -> 0 | I15: =G15*H15 -> 0
F16: =C16*E16 -> 0 | I16: =G16*H16 -> 0
F17: =C17*E17 -> 0 | I17: =G17*H17 -> 0
F18: =C18*E18 -> 0 | I18: =G18*H18 -> 0
C19: MATERIAL TOTAL: | F19: =SUM(F6:F18) -> 0 | G19: LABOR TOTAL: | I19: =SUM(I6:I18) -> 0
A20: TOTAL TI MATERIAL AND LABOR: | I20: =SUM(I19,F19) -> 0
A21: SHELL Cost Estimate for Division 5 (examples: structural, grates, decking, joists, stairs, railings, custom fabrications)
A22: DESCRIPTION | C22: MATERIAL | G22: LABOR
C23: QUANTITY | D23: UNIT | E23: COST | F23: TOTAL | G23: HOURS | H23: Labor Rate | I23: TOTAL
C24: 1 | E24: 0 | F24: =C24*E24 -> 0 | G24: 1 | H24: 0 | I24: =G24*H24 -> 0
F25: =C25*E25 -> 0 | I25: =G25*H25 -> 0
F26: =C26*E26 -> 0 | I26: =G26*H26 -> 0
F27: =C27*E27 -> 0 | I27: =G27*H27 -> 0
F28: =C28*E28 -> 0 | I28: =G28*H28 -> 0
F29: =C29*E29 -> 0 | I29: =G29*H29 -> 0
F30: =C30*E30 -> 0 | I30: =G30*H30 -> 0
F31: =C31*E31 -> 0 | I31: =G31*H31 -> 0
F32: =C32*E32 -> 0 | I32: =G32*H32 -> 0
F33: =C33*E33 -> 0 | I33: =G33*H33 -> 0
F34: =C34*E34 -> 0 | I34: =G34*H34 -> 0
F35: =C35*E35 -> 0 | I35: =G35*H35 -> 0
F36: =C36*E36 -> 0 | I36: =G36*H36 -> 0
C37: MATERIAL TOTAL: | F37: =SUM(F24:F36) -> 0 | G37: LABOR TOTAL: | I37: =SUM(I24:I36) -> 0
A38: TOTAL SHELL MATERIAL AND LABOR: | I38: =SUM(I37,F37) -> 0

Sheet 6
A1: DIVISION 6 - WOOD, PLASTICS, COMPOSITES | G1: FOR: | I1: DATE PREPARED:
G2: =IF(INPUT!C3=0,"",INPUT!C3) -> RLP # 36C248-25-R-0110 – EXHIBIT K | I2: =IF(INPUT!C10=0,"",INPUT!C10)
A3: Tentant Improvement (TI) Cost Estimate for Division 6 (examples: wood framing, rough carpentry, sheathing, millwork, decking, paneling, stairs & railings)
A4: DESCRIPTION | C4: MATERIAL | G4: LABOR
C5: QUANTITY | D5: UNIT | E5: COST | F5: TOTAL | G5: HOURS | H5: Labor Rate | I5: TOTAL
A6: Describe first item here | C6: 1 | D6: (ex: LF) | E6: 0 | F6: =C6*E6 -> 0 | G6: 1 | H6: 0 | I6: =G6*H6 -> 0
F7: =C7*E7 -> 0 | I7: =G7*H7 -> 0
F8: =C8*E8 -> 0 | I8: =G8*H8 -> 0
F9: =C9*E9 -> 0 | I9: =G9*H9 -> 0
F10: =C10*E10 -> 0 | I10: =G10*H10 -> 0
F11: =C11*E11 -> 0 | I11: =G11*H11 -> 0
F12: =C12*E12 -> 0 | I12: =G12*H12 -> 0
F13: =C13*E13 -> 0 | I13: =G13*H13 -> 0
F14: =C14*E14 -> 0 | I14: =G14*H14 -> 0
F15: =C15*E15 -> 0 | I15: =G15*H15 -> 0
F16: =C16*E16 -> 0 | I16: =G16*H16 -> 0
F17: =C17*E17 -> 0 | I17: =G17*H17 -> 0
F18: =C18*E18 -> 0 | I18: =G18*H18 -> 0
C19: MATERIAL TOTAL: | F19: =SUM(F6:F18) -> 0 | G19: LABOR TOTAL: | I19: =SUM(I6:I18) -> 0
A20: TOTAL TI MATERIAL AND LABOR: | I20: =SUM(I19,F19) -> 0
A21: SHELL Cost Estimate for Division 6 (examples: wood framing, rough carpentry, sheathing, millwork, decking, paneling, stairs & railings)
A22: DESCRIPTION | C22: MATERIAL | G22: LABOR
C23: QUANTITY | D23: UNIT | E23: COST | F23: TOTAL | G23: HOURS | H23: Labor Rate | I23: TOTAL
C24: 1 | E24: 0 | F24: =C24*E24 -> 0 | G24: 1 | H24: 0 | I24: =G24*H24 -> 0
F25: =C25*E25 -> 0 | I25: =G25*H25 -> 0
F26: =C26*E26 -> 0 | I26: =G26*H26 -> 0
F27: =C27*E27 -> 0 | I27: =G27*H27 -> 0
F28: =C28*E28 -> 0 | I28: =G28*H28 -> 0
F29: =C29*E29 -> 0 | I29: =G29*H29 -> 0
F30: =C30*E30 -> 0 | I30: =G30*H30 -> 0
F31: =C31*E31 -> 0 | I31: =G31*H31 -> 0
F32: =C32*E32 -> 0 | I32: =G32*H32 -> 0
F33: =C33*E33 -> 0 | I33: =G33*H33 -> 0
F34: =C34*E34 -> 0 | I34: =G34*H34 -> 0
F35: =C35*E35 -> 0 | I35: =G35*H35 -> 0
F36: =C36*E36 -> 0 | I36: =G36*H36 -> 0
C37: MATERIAL TOTAL: | F37: =SUM(F24:F36) -> 0 | G37: LABOR TOTAL: | I37: =SUM(I24:I36) -> 0
A38: TOTAL SHELL MATERIAL AND LABOR: | I38: =SUM(I37,F37) -> 0

Sheet 7
A1: DIVISION 7 - THERMAL & MOISTURE PROTECTION | G1: FOR: | I1: DATE PREPARED:
G2: =IF(INPUT!C3=0,"",INPUT!C3) -> RLP # 36C248-25-R-0110 – EXHIBIT K | I2: =IF(INPUT!C10=0,"",INPUT!C10)
A3: Tentant Improvement (TI) Cost Estimate for Division 7 (examples: roof Penetration/Patching, firestopping, joint sealants, caulking, dampproofing, insulation, weather barriers)
A4: DESCRIPTION | C4: MATERIAL | G4: LABOR
C5: QUANTITY | D5: UNIT | E5: COST | F5: TOTAL | G5: HOURS | H5: Labor Rate | I5: TOTAL
A6: Describe first item here | C6: 1 | D6: (ex: LF) | E6: 0 | F6: =C6*E6 -> 0 | G6: 1 | H6: 0 | I6: =G6*H6 -> 0
F7: =C7*E7 -> 0 | I7: =G7*H7 -> 0
F8: =C8*E8 -> 0 | I8: =G8*H8 -> 0
F9: =C9*E9 -> 0 | I9: =G9*H9 -> 0
F10: =C10*E10 -> 0 | I10: =G10*H10 -> 0
F11: =C11*E11 -> 0 | I11: =G11*H11 -> 0
F12: =C12*E12 -> 0 | I12: =G12*H12 -> 0
F13: =C13*E13 -> 0 | I13: =G13*H13 -> 0
F14: =C14*E14 -> 0 | I14: =G14*H14 -> 0
F15: =C15*E15 -> 0 | I15: =G15*H15 -> 0
F16: =C16*E16 -> 0 | I16: =G16*H16 -> 0
F17: =C17*E17 -> 0 | I17: =G17*H17 -> 0
F18: =C18*E18 -> 0 | I18: =G18*H18 -> 0
C19: MATERIAL TOTAL: | F19: =SUM(F6:F18) -> 0 | G19: LABOR TOTAL: | I19: =SUM(I6:I18) -> 0
A20: TOTAL TI MATERIAL AND LABOR: | I20: =SUM(I19,F19) -> 0
A21: SHELL Cost Estimate for Division 7 (examples: roof Penetration/Patching, firestopping, joint sealants, caulking, dampproofing, insulation, weather barriers)
A22: DESCRIPTION | C22: MATERIAL | G22: LABOR
C23: QUANTITY | D23: UNIT | E23: COST | F23: TOTAL | G23: HOURS | H23: Labor Rate | I23: TOTAL
C24: 1 | E24: 0 | F24: =C24*E24 -> 0 | G24: 1 | H24: 0 | I24: =G24*H24 -> 0
F25: =C25*E25 -> 0 | I25: =G25*H25 -> 0
F26: =C26*E26 -> 0 | I26: =G26*H26 -> 0
F27: =C27*E27 -> 0 | I27: =G27*H27 -> 0
F28: =C28*E28 -> 0 | I28: =G28*H28 -> 0
F29: =C29*E29 -> 0 | I29: =G29*H29 -> 0
F30: =C30*E30 -> 0 | I30: =G30*H30 -> 0
F31: =C31*E31 -> 0 | I31: =G31*H31 -> 0
F32: =C32*E32 -> 0 | I32: =G32*H32 -> 0
F33: =C33*E33 -> 0 | I33: =G33*H33 -> 0
F34: =C34*E34 -> 0 | I34: =G34*H34 -> 0
F35: =C35*E35 -> 0 | I35: =G35*H35 -> 0
F36: =C36*E36 -> 0 | I36: =G36*H36 -> 0
C37: MATERIAL TOTAL: | F37: =SUM(F24:F36) -> 0 | G37: LABOR TOTAL: | I37: =SUM(I24:I36) -> 0
A38: TOTAL SHELL MATERIAL AND LABOR: | I38: =SUM(I37,F37) -> 0

Sheet 8
A1: DIVISION 8 - OPENINGS | G1: FOR: | I1: DATE PREPARED:
G2: =IF(INPUT!C3=0,"",INPUT!C3) -> RLP # 36C248-25-R-0110 – EXHIBIT K | I2: =IF(INPUT!C10=0,"",INPUT!C10)
A3: Tentant Improvement (TI) Cost Estimate for Division 8 (examples: doors, frames, hardware, louvers, windows, glazing, curtainwall)
A4: DESCRIPTION | C4: MATERIAL | G4: LABOR
C5: QUANTITY | D5: UNIT | E5: COST | F5: TOTAL | G5: HOURS | H5: Labor Rate | I5: TOTAL
A6: Describe first item here | C6: 1 | D6: (ex: LF) | E6: 0 | F6: =C6*E6 -> 0 | G6: 1 | H6: 0 | I6: =G6*H6 -> 0
F7: =C7*E7 -> 0 | I7: =G7*H7 -> 0
F8: =C8*E8 -> 0 | I8: =G8*H8 -> 0
F9: =C9*E9 -> 0 | I9: =G9*H9 -> 0
F10: =C10*E10 -> 0 | I10: =G10*H10 -> 0
F11: =C11*E11 -> 0 | I11: =G11*H11 -> 0
F12: =C12*E12 -> 0 | I12: =G12*H12 -> 0
F13: =C13*E13 -> 0 | I13: =G13*H13 -> 0
F14: =C14*E14 -> 0 | I14: =G14*H14 -> 0
F15: =C15*E15 -> 0 | I15: =G15*H15 -> 0
F16: =C16*E16 -> 0 | I16: =G16*H16 -> 0
F17: =C17*E17 -> 0 | I17: =G17*H17 -> 0
F18: =C18*E18 -> 0 | I18: =G18*H18 -> 0
... F30: =C30*E30 -> 0 | I30: =G30*H30 -> 0
C31: MATERIAL TOTAL: | F31: =SUM(F6:F30) -> 0 | G31: LABOR TOTAL: | I31: =SUM(I6:I30) -> 0
A32: TOTAL TI MATERIAL AND LABOR: | I32: =SUM(I31,F31) -> 0
A33: SHELL Cost Estimate for Division 8 (examples: doors, frames, hardware, louvers, windows, glazing, curtainwall)
A34: DESCRIPTION | C34: MATERIAL | G34: LABOR
C35: QUANTITY | D35: UNIT | E35: COST | F35: TOTAL | G35: HOURS | H35: Labor Rate | I35: TOTAL
C36: 1 | E36: 0 | F36: =C36*E36 -> 0 | G36: 1 | H36: 0 | I36: =G36*H36 -> 0
F37: =C37*E37 -> 0 | I37: =G37*H37 -> 0
F38: =C38*E38 -> 0 | I38: =G38*H38 -> 0
F39: =C39*E39 -> 0 | I39: =G39*H39 -> 0
F40: =C40*E40 -> 0 | I40: =G40*H40 -> 0
F41: =C41*E41 -> 0 | I41: =G41*H41 -> 0
F42: =C42*E42 -> 0 | I42: =G42*H42 -> 0
F43: =C43*E43 -> 0 | I43: =G43*H43 -> 0
F44: =C44*E44 -> 0 | I44: =G44*H44 -> 0
F45: =C45*E45 -> 0 | I45: =G45*H45 -> 0
F46: =C46*E46 -> 0 | I46: =G46*H46 -> 0
F47: =C47*E47 -> 0 | I47: =G47*H47 -> 0
F48: =C48*E48 -> 0 | I48: =G48*H48 -> 0
... F58: =C58*E58 -> 0 | I58: =G58*H58 -> 0
C59: MATERIAL TOTAL: | F59: =SUM(F36:F58) -> 0 | G59: LABOR TOTAL: | I59: =SUM(I36:I58) -> 0
A60: TOTAL SHELL MATERIAL AND LABOR: | I60: =SUM(I59,F59) -> 0

Sheet 9
A1: DIVISION 9 - FINISHES | G1: FOR: | I1: DATE PREPARED:
G2: =IF(INPUT!C3=0,"",INPUT!C3) -> RLP # 36C248-25-R-0110 – EXHIBIT K | I2: =IF(INPUT!C10=0,"",INPUT!C10)
A3: Tentant Improvement (TI) Cost Estimate for Division 9 (examples: painting, carpeting, flooring & base, wall protection, walls)
A4: DESCRIPTION | C4: MATERIAL | G4: LABOR
C5: QUANTITY | D5: UNIT | E5: COST | F5: TOTAL | G5: HOURS | H5: Labor Rate | I5: TOTAL
A6: Describe first item here | C6: 1 | D6: (ex: LF) | E6: 0 | F6: =C6*E6 -> 0 | G6: 1 | H6: 0 | I6: =G6*H6 -> 0
F7: =C7*E7 -> 0 | I7: =G7*H7 -> 0
F8: =C8*E8 -> 0 | I8: =G8*H8 -> 0
F9: =C9*E9 -> 0 | I9: =G9*H9 -> 0
F10: =C10*E10 -> 0 | I10: =G10*H10 -> 0
F11: =C11*E11 -> 0 | I11: =G11*H11 -> 0
F12: =C12*E12 -> 0 | I12: =G12*H12 -> 0
F13: =C13*E13 -> 0 | I13: =G13*H13 -> 0
F14: =C14*E14 -> 0 | I14: =G14*H14 -> 0
F15: =C15*E15 -> 0 | I15: =G15*H15 -> 0
F16: =C16*E16 -> 0 | I16: =G16*H16 -> 0
F17: =C17*E17 -> 0 | I17: =G17*H17 -> 0
F18: =C18*E18 -> 0 | I18: =G18*H18 -> 0
... F30: =C30*E30 -> 0 | I30: =G30*H30 -> 0
C31: MATERIAL TOTAL: | F31: =SUM(F6:F30) -> 0 | G31: LABOR TOTAL: | I31: =SUM(I6:I30) -> 0
A32: TOTAL TI MATERIAL AND LABOR: | I32: =SUM(I31,F31) -> 0
A33: SHELL Cost Estimate for Division 9 (examples: painting, carpeting, flooring & base, wall protection, walls)
A34: DESCRIPTION | C34: MATERIAL | G34: LABOR
C35: QUANTITY | D35: UNIT | E35: COST | F35: TOTAL | G35: HOURS | H35: Labor Rate | I35: TOTAL
C36: 1 | E36: 0 | F36: =C36*E36 -> 0 | G36: 1 | H36: 0 | I36: =G36*H36 -> 0
F37: =C37*E37 -> 0 | I37: =G37*H37 -> 0
F38: =C38*E38 -> 0 | I38: =G38*H38 -> 0
F39: =C39*E39 -> 0 | I39: =G39*H39 -> 0
F40: =C40*E40 -> 0 | I40: =G40*H40 -> 0
F41: =C41*E41 -> 0 | I41: =G41*H41 -> 0
F42: =C42*E42 -> 0 | I42: =G42*H42 -> 0
F43: =C43*E43 -> 0 | I43: =G43*H43 -> 0
F44: =C44*E44 -> 0 | I44: =G44*H44 -> 0
F45: =C45*E45 -> 0 | I45: =G45*H45 -> 0
F46: =C46*E46 -> 0 | I46: =G46*H46 -> 0
F47: =C47*E47 -> 0 | I47: =G47*H47 -> 0
F48: =C48*E48 -> 0 | I48: =G48*H48 -> 0
... F58: =C58*E58 -> 0 | I58: =G58*H58 -> 0
C59: MATERIAL TOTAL: | F59: =SUM(F36:F58) -> 0 | G59: LABOR TOTAL: | I59: =SUM(I36:I58) -> 0
A60: TOTAL SHELL MATERIAL AND LABOR: | I60: =SUM(I59,F59) -> 0

Sheet 10
A1: DIVISION 10 - SPECIALTIES | G1: FOR: | I1: DATE PREPARED:
G2: =IF(INPUT!C3=0,"",INPUT!C3) -> RLP # 36C248-25-R-0110 – EXHIBIT K | I2: =IF(INPUT!C10=0,"",INPUT!C10)
A3: Tentant Improvement (TI) Cost Estimate for Division 10 (examples: displays, signage, directory boards, movable partitions, wall and door protection, lockers, flagpoles, storage assemblies)
A4: DESCRIPTION | C4: MATERIAL | G4: LABOR
C5: QUANTITY | D5: UNIT | E5: COST | F5: TOTAL | G5: HOURS | H5: Labor Rate | I5: TOTAL
A6: Describe first item here | C6: 1 | D6: (ex: LF) | E6: 0 | F6: =C6*E6 -> 0 | G6: 1 | H6: 0 | I6: =G6*H6 -> 0
F7: =C7*E7 -> 0 | I7: =G7*H7 -> 0
F8: =C8*E8 -> 0 | I8: =G8*H8 -> 0
F9: =C9*E9 -> 0 | I9: =G9*H9 -> 0
F10: =C10*E10 -> 0 | I10: =G10*H10 -> 0
F11: =C11*E11 -> 0 | I11: =G11*H11 -> 0
F12: =C12*E12 -> 0 | I12: =G12*H12 -> 0
F13: =C13*E13 -> 0 | I13: =G13*H13 -> 0
F14: =C14*E14 -> 0 | I14: =G14*H14 -> 0
F15: =C15*E15 -> 0 | I15: =G15*H15 -> 0
F16: =C16*E16 -> 0 | I16: =G16*H16 -> 0
F17: =C17*E17 -> 0 | I17: =G17*H17 -> 0
F18: =C18*E18 -> 0 | I18: =G18*H18 -> 0
C19: MATERIAL TOTAL: | F19: =SUM(F6:F18) -> 0 | G19: LABOR TOTAL: | I19: =SUM(I6:I18) -> 0
A20: TOTAL TI MATERIAL AND LABOR: | I20: =SUM(I19,F19) -> 0
A21: SHELL Cost Estimate for Division 10 (examples: displays, signage, directory boards, movable partitions, wall and door protection, lockers, flagpoles, storage assemblies)
A22: DESCRIPTION | C22: MATERIAL | G22: LABOR
C23: QUANTITY | D23: UNIT | E23: COST | F23: TOTAL | G23: HOURS | H23: Labor Rate | I23: TOTAL
C24: 1 | E24: 0 | F24: =C24*E24 -> 0 | G24: 1 | H24: 0 | I24: =G24*H24 -> 0
F25: =C25*E25 -> 0 | I25: =G25*H25 -> 0
F26: =C26*E26 -> 0 | I26: =G26*H26 -> 0
F27: =C27*E27 -> 0 | I27: =G27*H27 -> 0
F28: =C28*E28 -> 0 | I28: =G28*H28 -> 0
F29: =C29*E29 -> 0 | I29: =G29*H29 -> 0
F30: =C30*E30 -> 0 | I30: =G30*H30 -> 0
F31: =C31*E31 -> 0 | I31: =G31*H31 -> 0
F32: =C32*E32 -> 0 | I32: =G32*H32 -> 0
F33: =C33*E33 -> 0 | I33: =G33*H33 -> 0
F34: =C34*E34 -> 0 | I34: =G34*H34 -> 0
F35: =C35*E35 -> 0 | I35: =G35*H35 -> 0
F36: =C36*E36 -> 0 | I36: =G36*H36 -> 0
C37: MATERIAL TOTAL: | F37: =SUM(F24:F36) -> 0 | G37: LABOR TOTAL: | I37: =SUM(I24:I36) -> 0
A38: TOTAL SHELL MATERIAL AND LABOR: | I38: =SUM(I37,F37) -> 0

Sheet 11
A1: DIVISION 11 - EQUIPMENT | G1: FOR: | I1: DATE PREPARED:
G2: =IF(INPUT!C3=0,"",INPUT!C3) -> RLP # 36C248-25-R-0110 – EXHIBIT K | I2: =IF(INPUT!C10=0,"",INPUT!C10)
A3: Tentant Improvement (TI) Cost Estimate for Division 11 (examples: AV, lab, recreational, food, banking, medical, retail, parking, loading dock, and other equipment)
A4: DESCRIPTION | C4: MATERIAL | G4: LABOR
C5: QUANTITY | D5: UNIT | E5: COST | F5: TOTAL | G5: HOURS | H5: Labor Rate | I5: TOTAL
A6: Describe first item here | C6: 1 | D6: (ex: LF) | E6: 0 | F6: =C6*E6 -> 0 | G6: 1 | H6: 0 | I6: =G6*H6 -> 0
F7: =C7*E7 -> 0 | I7: =G7*H7 -> 0
F8: =C8*E8 -> 0 | I8: =G8*H8 -> 0
F9: =C9*E9 -> 0 | I9: =G9*H9 -> 0
F10: =C10*E10 -> 0 | I10: =G10*H10 -> 0
F11: =C11*E11 -> 0 | I11: =G11*H11 -> 0
F12: =C12*E12 -> 0 | I12: =G12*H12 -> 0
F13: =C13*E13 -> 0 | I13: =G13*H13 -> 0
F14: =C14*E14 -> 0 | I14: =G14*H14 -> 0
F15: =C15*E15 -> 0 | I15: =G15*H15 -> 0
F16: =C16*E16 -> 0 | I16: =G16*H16 -> 0
F17: =C17*E17 -> 0 | I17: =G17*H17 -> 0
F18: =C18*E18 -> 0 | I18: =G18*H18 -> 0
C19: MATERIAL TOTAL: | F19: =SUM(F6:F18) -> 0 | G19: LABOR TOTAL: | I19: =SUM(I6:I18) -> 0
A20: TOTAL TI MATERIAL AND LABOR: | I20: =SUM(I19,F19) -> 0
A21: SHELL Cost Estimate for Division 11 (examples: AV, lab, recreational, food, banking, medical, retail, parking, loading dock, and other equipment)
A22: DESCRIPTION | C22: MATERIAL | G22: LABOR
C23: QUANTITY | D23: UNIT | E23: COST | F23: TOTAL | G23: HOURS | H23: Labor Rate | I23: TOTAL
C24: 1 | E24: 0 | F24: =C24*E24 -> 0 | G24: 1 | H24: 0 | I24: =G24*H24 -> 0
F25: =C25*E25 -> 0 | I25: =G25*H25 -> 0
F26: =C26*E26 -> 0 | I26: =G26*H26 -> 0
F27: =C27*E27 -> 0 | I27: =G27*H27 -> 0
F28: =C28*E28 -> 0 | I28: =G28*H28 -> 0
F29: =C29*E29 -> 0 | I29: =G29*H29 -> 0
F30: =C30*E30 -> 0 | I30: =G30*H30 -> 0
F31: =C31*E31 -> 0 | I31: =G31*H31 -> 0
F32: =C32*E32 -> 0 | I32: =G32*H32 -> 0
F33: =C33*E33 -> 0 | I33: =G33*H33 -> 0
F34: =C34*E34 -> 0 | I34: =G34*H34 -> 0
F35: =C35*E35 -> 0 | I35: =G35*H35 -> 0
F36: =C36*E36 -> 0 | I36: =G36*H36 -> 0
C37: MATERIAL TOTAL: | F37: =SUM(F24:F36) -> 0 | G37: LABOR TOTAL: | I37: =SUM(I24:I36) -> 0
A38: TOTAL SHELL MATERIAL AND LABOR: | I38: =SUM(I37,F37) -> 0

Sheet 12
A1: DIVISION 12 - FURNISHINGS | G1: FOR: | I1: DATE PREPARED:
G2: =IF(INPUT!C3=0,"",INPUT!C3) -> RLP # 36C248-25-R-0110 – EXHIBIT K | I2: =IF(INPUT!C10=0,"",INPUT!C10)
A3: Tentant Improvement (TI) Cost Estimate for Division 12 (examples: decorations, systems and office funiture, casework, countertops)
A4: DESCRIPTION | C4: MATERIAL | G4: LABOR
C5: QUANTITY | D5: UNIT | E5: COST | F5: TOTAL | G5: HOURS | H5: Labor Rate | I5: TOTAL
A6: Describe first item here | C6: 1 | D6: (ex: LF) | E6: 0 | F6: =C6*E6 -> 0 | G6: 1 | H6: 0 | I6: =G6*H6 -> 0
F7: =C7*E7 -> 0 | I7: =G7*H7 -> 0
F8: =C8*E8 -> 0 | I8: =G8*H8 -> 0
F9: =C9*E9 -> 0 | I9: =G9*H9 -> 0
F10: =C10*E10 -> 0 | I10: =G10*H10 -> 0
F11: =C11*E11 -> 0 | I11: =G11*H11 -> 0
F12: =C12*E12 -> 0 | I12: =G12*H12 -> 0
F13: =C13*E13 -> 0 | I13: =G13*H13 -> 0
F14: =C14*E14 -> 0 | I14: =G14*H14 -> 0
F15: =C15*E15 -> 0 | I15: =G15*H15 -> 0
F16: =C16*E16 -> 0 | I16: =G16*H16 -> 0
F17: =C17*E17 -> 0 | I17: =G17*H17 -> 0
F18: =C18*E18 -> 0 | I18: =G18*H18 -> 0
... F30: =C30*E30 -> 0 | I30: =G30*H30 -> 0
C31: MATERIAL TOTAL: | F31: =SUM(F6:F30) -> 0 | G31: LABOR TOTAL: | I31: =SUM(I6:I30) -> 0
A32: TOTAL TI MATERIAL AND LABOR: | I32: =SUM(I31,F31) -> 0
A33: SHELL Cost Estimate for Division 12 (examples: decorations, systems and office funiture, casework, countertops)
A34: DESCRIPTION | C34: MATERIAL | G34: LABOR
C35: QUANTITY | D35: UNIT | E35: COST | F35: TOTAL | G35: HOURS | H35: Labor Rate | I35: TOTAL
C36: 1 | E36: 0 | F36: =C36*E36 -> 0 | G36: 1 | H36: 0 | I36: =G36*H36 -> 0
F37: =C37*E37 -> 0 | I37: =G37*H37 -> 0
F38: =C38*E38 -> 0 | I38: =G38*H38 -> 0
F39: =C39*E39 -> 0 | I39: =G39*H39 -> 0
F40: =C40*E40 -> 0 | I40: =G40*H40 -> 0
F41: =C41*E41 -> 0 | I41: =G41*H41 -> 0
F42: =C42*E42 -> 0 | I42: =G42*H42 -> 0
F43: =C43*E43 -> 0 | I43: =G43*H43 -> 0
F44: =C44*E44 -> 0 | I44: =G44*H44 -> 0
F45: =C45*E45 -> 0 | I45: =G45*H45 -> 0
F46: =C46*E46 -> 0 | I46: =G46*H46 -> 0
F47: =C47*E47 -> 0 | I47: =G47*H47 -> 0
F48: =C48*E48 -> 0 | I48: =G48*H48 -> 0
C49: MATERIAL TOTAL: | F49: =SUM(F36:F48) -> 0 | G49: LABOR TOTAL: | I49: =SUM(I36:I48) -> 0
A50: TOTAL SHELL MATERIAL AND LABOR: | I50: =SUM(I49,F49) -> 0

Sheet 13
A1: DIVISION 13 - SPECIAL CONSTRUCTION | G1: FOR: | I1: DATE PREPARED:
G2: =IF(INPUT!C3=0,"",INPUT!C3) -> RLP # 36C248-25-R-0110 – EXHIBIT K | I2: =IF(INPUT!C10=0,"",INPUT!C10)
A3: Tentant Improvement (TI) Cost Estimate for Division 13 (examples: pre-engineered & prefab structures)
A4: DESCRIPTION | C4: MATERIAL | G4: LABOR
C5: QUANTITY | D5: UNIT | E5: COST | F5: TOTAL | G5: HOURS | H5: Labor Rate | I5: TOTAL
A6: Describe first item here | C6: 1 | D6: (ex: LF) | E6: 0 | F6: =C6*E6 -> 0 | G6: 1 | H6: 0 | I6: =G6*H6 -> 0
F7: =C7*E7 -> 0 | I7: =G7*H7 -> 0
F8: =C8*E8 -> 0 | I8: =G8*H8 -> 0
F9: =C9*E9 -> 0 | I9: =G9*H9 -> 0
F10: =C10*E10 -> 0 | I10: =G10*H10 -> 0
F11: =C11*E11 -> 0 | I11: =G11*H11 -> 0
F12: =C12*E12 -> 0 | I12: =G12*H12 -> 0
F13: =C13*E13 -> 0 | I13: =G13*H13 -> 0
F14: =C14*E14 -> 0 | I14: =G14*H14 -> 0
F15: =C15*E15 -> 0 | I15: =G15*H15 -> 0
F16: =C16*E16 -> 0 | I16: =G16*H16 -> 0
F17: =C17*E17 -> 0 | I17: =G17*H17 -> 0
F18: =C18*E18 -> 0 | I18: =G18*H18 -> 0
C19: MATERIAL TOTAL: | F19: =SUM(F6:F18) -> 0 | G19: LABOR TOTAL: | I19: =SUM(I6:I18) -> 0
A20: TOTAL TI MATERIAL AND LABOR: | I20: =SUM(I19,F19) -> 0
A21: SHELL Cost Estimate for Division 13 (examples: pre-engineered & prefab structures)
A22: DESCRIPTION | C22: MATERIAL | G22: LABOR
C23: QUANTITY | D23: UNIT | E23: COST | F23: TOTAL | G23: HOURS | H23: Labor Rate | I23: TOTAL
C24: 1 | E24: 0 | F24: =C24*E24 -> 0 | G24: 1 | H24: 0 | I24: =G24*H24 -> 0
F25: =C25*E25 -> 0 | I25: =G25*H25 -> 0
F26: =C26*E26 -> 0 | I26: =G26*H26 -> 0
F27: =C27*E27 -> 0 | I27: =G27*H27 -> 0
F28: =C28*E28 -> 0 | I28: =G28*H28 -> 0
F29: =C29*E29 -> 0 | I29: =G29*H29 -> 0
F30: =C30*E30 -> 0 | I30: =G30*H30 -> 0
F31: =C31*E31 -> 0 | I31: =G31*H31 -> 0
F32: =C32*E32 -> 0 | I32: =G32*H32 -> 0
F33: =C33*E33 -> 0 | I33: =G33*H33 -> 0
F34: =C34*E34 -> 0 | I34: =G34*H34 -> 0
F35: =C35*E35 -> 0 | I35: =G35*H35 -> 0
F36: =C36*E36 -> 0 | I36: =G36*H36 -> 0
C37: MATERIAL TOTAL: | F37: =SUM(F24:F36) -> 0 | G37: LABOR TOTAL: | I37: =SUM(I24:I36) -> 0
A38: TOTAL SHELL MATERIAL AND LABOR: | I38: =SUM(I37,F37) -> 0

Sheet 14
A1: DIVISION 14 - CONVEYING EQUIPMENT | G1: FOR: | I1: DATE PREPARED:
G2: =IF(INPUT!C3=0,"",INPUT!C3) -> RLP # 36C248-25-R-0110 – EXHIBIT K | I2: =IF(INPUT!C10=0,"",INPUT!C10)
A3: Tentant Improvement (TI) Cost Estimate for Division 14
A4: DESCRIPTION | C4: MATERIAL | G4: LABOR
C5: QUANTITY | D5: UNIT | E5: COST | F5: TOTAL | G5: HOURS | H5: Labor Rate | I5: TOTAL
A6: Describe first item here | C6: 1 | D6: (ex: LF) | E6: 0 | F6: =C6*E6 -> 0 | G6: 1 | H6: 0 | I6: =G6*H6 -> 0
F7: =C7*E7 -> 0 | I7: =G7*H7 -> 0
F8: =C8*E8 -> 0 | I8: =G8*H8 -> 0
F9: =C9*E9 -> 0 | I9: =G9*H9 -> 0
F10: =C10*E10 -> 0 | I10: =G10*H10 -> 0
F11: =C11*E11 -> 0 | I11: =G11*H11 -> 0
F12: =C12*E12 -> 0 | I12: =G12*H12 -> 0
F13: =C13*E13 -> 0 | I13: =G13*H13 -> 0
F14: =C14*E14 -> 0 | I14: =G14*H14 -> 0
F15: =C15*E15 -> 0 | I15: =G15*H15 -> 0
F16: =C16*E16 -> 0 | I16: =G16*H16 -> 0
F17: =C17*E17 -> 0 | I17: =G17*H17 -> 0
F18: =C18*E18 -> 0 | I18: =G18*H18 -> 0
C19: MATERIAL TOTAL: | F19: =SUM(F6:F18) -> 0 | G19: LABOR TOTAL: | I19: =SUM(I6:I18) -> 0
A20: TOTAL TI MATERIAL AND LABOR: | I20: =SUM(I19,F19) -> 0
A21: SHELL Cost Estimate for Division 14
A22: DESCRIPTION | C22: MATERIAL | G22: LABOR
C23: QUANTITY | D23: UNIT | E23: COST | F23: TOTAL | G23: HOURS | H23: Labor Rate | I23: TOTAL
C24: 1 | E24: 0 | F24: =C24*E24 -> 0 | G24: 1 | H24: 0 | I24: =G24*H24 -> 0
F25: =C25*E25 -> 0 | I25: =G25*H25 -> 0
F26: =C26*E26 -> 0 | I26: =G26*H26 -> 0
F27: =C27*E27 -> 0 | I27: =G27*H27 -> 0
F28: =C28*E28 -> 0 | I28: =G28*H28 -> 0
F29: =C29*E29 -> 0 | I29: =G29*H29 -> 0
F30: =C30*E30 -> 0 | I30: =G30*H30 -> 0
F31: =C31*E31 -> 0 | I31: =G31*H31 -> 0
F32: =C32*E32 -> 0 | I32: =G32*H32 -> 0
F33: =C33*E33 -> 0 | I33: =G33*H33 -> 0
F34: =C34*E34 -> 0 | I34: =G34*H34 -> 0
F35: =C35*E35 -> 0 | I35: =G35*H35 -> 0
F36: =C36*E36 -> 0 | I36: =G36*H36 -> 0
C37: MATERIAL TOTAL: | F37: =SUM(F24:F36) -> 0 | G37: LABOR TOTAL: | I37: =SUM(I24:I36) -> 0
A38: TOTAL SHELL MATERIAL AND LABOR: | I38: =SUM(I37,F37) -> 0

Sheet 21
A1: DIVISION 21 - FIRE SUPPRESSION | G1: FOR: | I1: DATE PREPARED:
G2: =IF(INPUT!C3=0,"",INPUT!C3) -> RLP # 36C248-25-R-0110 – EXHIBIT K | I2: =IF(INPUT!C10=0,"",INPUT!C10)
A3: Tentant Improvement (TI) Cost Estimate for Division 21
A4: DESCRIPTION | C4: MATERIAL | G4: LABOR
C5: QUANTITY | D5: UNIT | E5: COST | F5: TOTAL | G5: HOURS | H5: Labor Rate | I5: TOTAL
A6: Describe first item here | C6: 1 | D6: (ex: LF) | E6: 0 | F6: =C6*E6 -> 0 | G6: 1 | H6: 0 | I6: =G6*H6 -> 0
F7: =C7*E7 -> 0 | I7: =G7*H7 -> 0
F8: =C8*E8 -> 0 | I8: =G8*H8 -> 0
F9: =C9*E9 -> 0 | I9: =G9*H9 -> 0
F10: =C10*E10 -> 0 | I10: =G10*H10 -> 0
F11: =C11*E11 -> 0 | I11: =G11*H11 -> 0
F12: =C12*E12 -> 0 | I12: =G12*H12 -> 0
F13: =C13*E13 -> 0 | I13: =G13*H13 -> 0
F14: =C14*E14 -> 0 | I14: =G14*H14 -> 0
F15: =C15*E15 -> 0 | I15: =G15*H15 -> 0
F16: =C16*E16 -> 0 | I16: =G16*H16 -> 0
F17: =C17*E17 -> 0 | I17: =G17*H17 -> 0
F18: =C18*E18 -> 0 | I18: =G18*H18 -> 0
C19: MATERIAL TOTAL: | F19: =SUM(F6:F18) -> 0 | G19: LABOR TOTAL: | I19: =SUM(I6:I18) -> 0
A20: TOTAL TI MATERIAL AND LABOR: | I20: =SUM(I19,F19) -> 0
A21: SHELL Cost Estimate for Division 21
A22: DESCRIPTION | C22: MATERIAL | G22: LABOR
C23: QUANTITY | D23: UNIT | E23: COST | F23: TOTAL | G23: HOURS | H23: Labor Rate | I23: TOTAL
C24: 1 | E24: 0 | F24: =C24*E24 -> 0 | G24: 1 | H24: 0 | I24: =G24*H24 -> 0
F25: =C25*E25 -> 0 | I25: =G25*H25 -> 0
F26: =C26*E26 -> 0 | I26: =G26*H26 -> 0
F27: =C27*E27 -> 0 | I27: =G27*H27 -> 0
F28: =C28*E28 -> 0 | I28: =G28*H28 -> 0
F29: =C29*E29 -> 0 | I29: =G29*H29 -> 0
F30: =C30*E30 -> 0 | I30: =G30*H30 -> 0
F31: =C31*E31 -> 0 | I31: =G31*H31 -> 0
F32: =C32*E32 -> 0 | I32: =G32*H32 -> 0
F33: =C33*E33 -> 0 | I33: =G33*H33 -> 0
F34: =C34*E34 -> 0 | I34: =G34*H34 -> 0
F35: =C35*E35 -> 0 | I35: =G35*H35 -> 0
F36: =C36*E36 -> 0 | I36: =G36*H36 -> 0
C37: MATERIAL TOTAL: | F37: =SUM(F24:F36) -> 0 | G37: LABOR TOTAL: | I37: =SUM(I24:I36) -> 0
A38: TOTAL SHELL MATERIAL AND LABOR: | I38: =SUM(I37,F37) -> 0

Sheet 22
A1: DIVISION 22 - PLUMBING | G1: FOR: | I1: DATE PREPARED:
G2: =IF(INPUT!C3=0,"",INPUT!C3) -> RLP # 36C248-25-R-0110 – EXHIBIT K | I2: =IF(INPUT!C10=0,"",INPUT!C10)
A3: Tentant Improvement (TI) Cost Estimate for Division 22
A4: DESCRIPTION | C4: MATERIAL | G4: LABOR
C5: QUANTITY | D5: UNIT | E5: COST | F5: TOTAL | G5: HOURS | H5: Labor Rate | I5: TOTAL
A6: Describe first item here | C6: 1 | D6: (ex: LF) | E6: 0 | F6: =C6*E6 -> 0 | G6: 1 | H6: 0 | I6: =G6*H6 -> 0
F7: =C7*E7 -> 0 | I7: =G7*H7 -> 0
F8: =C8*E8 -> 0 | I8: =G8*H8 -> 0
F9: =C9*E9 -> 0 | I9: =G9*H9 -> 0
F10: =C10*E10 -> 0 | I10: =G10*H10 -> 0
F11: =C11*E11 -> 0 | I11: =G11*H11 -> 0
F12: =C12*E12 -> 0 | I12: =G12*H12 -> 0
F13: =C13*E13 -> 0 | I13: =G13*H13 -> 0
F14: =C14*E14 -> 0 | I14: =G14*H14 -> 0
F15: =C15*E15 -> 0 | I15: =G15*H15 -> 0
F16: =C16*E16 -> 0 | I16: =G16*H16 -> 0
F17: =C17*E17 -> 0 | I17: =G17*H17 -> 0
F18: =C18*E18 -> 0 | I18: =G18*H18 -> 0
... F30: =C30*E30 -> 0 | I30: =G30*H30 -> 0
C31: MATERIAL TOTAL: | F31: =SUM(F6:F30) -> 0 | G31: LABOR TOTAL: | I31: =SUM(I6:I30) -> 0
A32: TOTAL TI MATERIAL AND LABOR: | I32: =SUM(I31,F31) -> 0
A33: SHELL Cost Estimate for Division 22
A34: DESCRIPTION | C34: MATERIAL | G34: LABOR
C35: QUANTITY | D35: UNIT | E35: COST | F35: TOTAL | G35: HOURS | H35: Labor Rate | I35: TOTAL
C36: 1 | E36: 0 | F36: =C36*E36 -> 0 | G36: 1 | H36: 0 | I36: =G36*H36 -> 0
F37: =C37*E37 -> 0 | I37: =G37*H37 -> 0
F38: =C38*E38 -> 0 | I38: =G38*H38 -> 0
F39: =C39*E39 -> 0 | I39: =G39*H39 -> 0
F40: =C40*E40 -> 0 | I40: =G40*H40 -> 0
F41: =C41*E41 -> 0 | I41: =G41*H41 -> 0
F42: =C42*E42 -> 0 | I42: =G42*H42 -> 0
F43: =C43*E43 -> 0 | I43: =G43*H43 -> 0
F44: =C44*E44 -> 0 | I44: =G44*H44 -> 0
F45: =C45*E45 -> 0 | I45: =G45*H45 -> 0
F46: =C46*E46 -> 0 | I46: =G46*H46 -> 0
F47: =C47*E47 -> 0 | I47: =G47*H47 -> 0
F48: =C48*E48 -> 0 | I48: =G48*H48 -> 0
C49: MATERIAL TOTAL: | F49: =SUM(F36:F48) -> 0 | G49: LABOR TOTAL: | I49: =SUM(I36:I48) -> 0
A50: TOTAL SHELL MATERIAL AND LABOR: | I50: =SUM(I49,F49) -> 0

Sheet 23
A1: DIVISION 23 - HEATING, VENTILATING, AND AIR CONDITIONING (HVAC) | G1: FOR: | I1: DATE PREPARED:
G2: =IF(INPUT!C3=0,"",INPUT!C3) -> RLP # 36C248-25-R-0110 – EXHIBIT K | I2: =IF(INPUT!C10=0,"",INPUT!C10)
A3: Tentant Improvement (TI) Cost Estimate for Division 23
A4: DESCRIPTION | C4: MATERIAL | G4: LABOR
C5: QUANTITY | D5: UNIT | E5: COST | F5: TOTAL | G5: HOURS | H5: Labor Rate | I5: TOTAL
A6: Describe first item here | C6: 1 | D6: (ex: LF) | E6: 0 | F6: =C6*E6 -> 0 | G6: 1 | H6: 0 | I6: =G6*H6 -> 0
F7: =C7*E7 -> 0 | I7: =G7*H7 -> 0
F8: =C8*E8 -> 0 | I8: =G8*H8 -> 0
F9: =C9*E9 -> 0 | I9: =G9*H9 -> 0
F10: =C10*E10 -> 0 | I10: =G10*H10 -> 0
F11: =C11*E11 -> 0 | I11: =G11*H11 -> 0
F12: =C12*E12 -> 0 | I12: =G12*H12 -> 0
F13: =C13*E13 -> 0 | I13: =G13*H13 -> 0
F14: =C14*E14 -> 0 | I14: =G14*H14 -> 0
F15: =C15*E15 -> 0 | I15: =G15*H15 -> 0
F16: =C16*E16 -> 0 | I16: =G16*H16 -> 0
F17: =C17*E17 -> 0 | I17: =G17*H17 -> 0
F18: =C18*E18 -> 0 | I18: =G18*H18 -> 0
... F30: =C30*E30 -> 0 | I30: =G30*H30 -> 0
C31: MATERIAL TOTAL: | F31: =SUM(F6:F30) -> 0 | G31: LABOR TOTAL: | I31: =SUM(I6:I30) -> 0
A32: TOTAL TI MATERIAL AND LABOR: | I32: =SUM(I31,F31) -> 0
A33: SHELL Cost Estimate for Division 23
A34: DESCRIPTION | C34: MATERIAL | G34: LABOR
C35: QUANTITY | D35: UNIT | E35: COST | F35: TOTAL | G35: HOURS | H35: Labor Rate | I35: TOTAL
C36: 1 | E36: 0 | F36: =C36*E36 -> 0 | G36: 1 | H36: 0 | I36: =G36*H36 -> 0
F37: =C37*E37 -> 0 | I37: =G37*H37 -> 0
F38: =C38*E38 -> 0 | I38: =G38*H38 -> 0
F39: =C39*E39 -> 0 | I39: =G39*H39 -> 0
F40: =C40*E40 -> 0 | I40: =G40*H40 -> 0
F41: =C41*E41 -> 0 | I41: =G41*H41 -> 0
F42: =C42*E42 -> 0 | I42: =G42*H42 -> 0
F43: =C43*E43 -> 0 | I43: =G43*H43 -> 0
F44: =C44*E44 -> 0 | I44: =G44*H44 -> 0
F45: =C45*E45 -> 0 | I45: =G45*H45 -> 0
F46: =C46*E46 -> 0 | I46: =G46*H46 -> 0
F47: =C47*E47 -> 0 | I47: =G47*H47 -> 0
F48: =C48*E48 -> 0 | I48: =G48*H48 -> 0
C49: MATERIAL TOTAL: | F49: =SUM(F36:F48) -> 0 | G49: LABOR TOTAL: | I49: =SUM(I36:I48) -> 0
A50: TOTAL SHELL MATERIAL AND LABOR: | I50: =SUM(I49,F49) -> 0

Sheet 26.1
A1: DIVISION 26.1 - ELECTRICAL | G1: FOR: | I1: DATE PREPARED:
G2: =IF(INPUT!C3=0,"",INPUT!C3) -> RLP # 36C248-25-R-0110 – EXHIBIT K | I2: =IF(INPUT!C10=0,"",INPUT!C10)
A3: Tentant Improvement (TI) Cost Estimate for Division 26.1 (examples: conduit, wire, supports, boxes, fittings, terminations, outlets, cover plates, receptacles, power devices, panels & breakers, electrical equipment)
A4: DESCRIPTION | C4: MATERIAL | G4: LABOR
C5: QUANTITY | D5: UNIT | E5: COST | F5: TOTAL | G5: HOURS | H5: Labor Rate | I5: TOTAL
A6: Describe first item here | C6: 1 | D6: (ex: LF) | E6: 0 | F6: =C6*E6 -> 0 | G6: 1 | H6: 0 | I6: =G6*H6 -> 0
F7: =C7*E7 -> 0 | I7: =G7*H7 -> 0
F8: =C8*E8 -> 0 | I8: =G8*H8 -> 0
F9: =C9*E9 -> 0 | I9: =G9*H9 -> 0
F10: =C10*E10 -> 0 | I10: =G10*H10 -> 0
F11: =C11*E11 -> 0 | I11: =G11*H11 -> 0
F12: =C12*E12 -> 0 | I12: =G12*H12 -> 0
F13: =C13*E13 -> 0 | I13: =G13*H13 -> 0
F14: =C14*E14 -> 0 | I14: =G14*H14 -> 0
F15: =C15*E15 -> 0 | I15: =G15*H15 -> 0
F16: =C16*E16 -> 0 | I16: =G16*H16 -> 0
F17: =C17*E17 -> 0 | I17: =G17*H17 -> 0
F18: =C18*E18 -> 0 | I18: =G18*H18 -> 0
... F30: =C30*E30 -> 0 | I30: =G30*H30 -> 0
C31: MATERIAL TOTAL: | F31: =SUM(F6:F30) -> 0 | G31: LABOR TOTAL: | I31: =SUM(I6:I30) -> 0
A32: TOTAL TI MATERIAL AND LABOR: | I32: =SUM(I31,F31) -> 0
A33: SHELL Cost Estimate for Division 26.1 (examples: conduit, wire, supports, boxes, fittings, terminations, outlets, cover plates, receptacles, power devices, panels & breakers, electrical equipment)
A34: DESCRIPTION | C34: MATERIAL | G34: LABOR
C35: QUANTITY | D35: UNIT | E35: COST | F35: TOTAL | G35: HOURS | H35: Labor Rate | I35: TOTAL
C36: 1 | E36: 0 | F36: =C36*E36 -> 0 | G36: 1 | H36: 0 | I36: =G36*H36 -> 0
F37: =C37*E37 -> 0 | I37: =G37*H37 -> 0
F38: =C38*E38 -> 0 | I38: =G38*H38 -> 0
F39: =C39*E39 -> 0 | I39: =G39*H39 -> 0
F40: =C40*E40 -> 0 | I40: =G40*H40 -> 0
F41: =C41*E41 -> 0 | I41: =G41*H41 -> 0
F42: =C42*E42 -> 0 | I42: =G42*H42 -> 0
F43: =C43*E43 -> 0 | I43: =G43*H43 -> 0
F44: =C44*E44 -> 0 | I44: =G44*H44 -> 0
F45: =C45*E45 -> 0 | I45: =G45*H45 -> 0
F46: =C46*E46 -> 0 | I46: =G46*H46 -> 0
F47: =C47*E47 -> 0 | I47: =G47*H47 -> 0
F48: =C48*E48 -> 0 | I48: =G48*H48 -> 0
C49: MATERIAL TOTAL: | F49: =SUM(F36:F48) -> 0 | G49: LABOR TOTAL: | I49: =SUM(I36:I48) -> 0
A50: TOTAL SHELL MATERIAL AND LABOR: | I50: =SUM(I49,F49) -> 0

Sheet 26.2
A1: DIVISION 26.2 - LIGHTING | G1: FOR: | I1: DATE PREPARED:
G2: =IF(INPUT!C3=0,"",INPUT!C3) -> RLP # 36C248-25-R-0110 – EXHIBIT K | I2: =IF(INPUT!C10=0,"",INPUT!C10)
A3: Tentant Improvement (TI) Cost Estimate for Division 26.2 (examples: lighting fixtures, wall switches, motion switches)
A4: DESCRIPTION | C4: MATERIAL | G4: LABOR
C5: QUANTITY | D5: UNIT | E5: COST | F5: TOTAL | G5: HOURS | H5: Labor Rate | I5: TOTAL
A6: Describe first item here | C6: 1 | D6: (ex: LF) | E6: 0 | F6: =C6*E6 -> 0 | G6: 1 | H6: 0 | I6: =G6*H6 -> 0
F7: =C7*E7 -> 0 | I7: =G7*H7 -> 0
F8: =C8*E8 -> 0 | I8: =G8*H8 -> 0
F9: =C9*E9 -> 0 | I9: =G9*H9 -> 0
F10: =C10*E10 -> 0 | I10: =G10*H10 -> 0
F11: =C11*E11 -> 0 | I11: =G11*H11 -> 0
F12: =C12*E12 -> 0 | I12: =G12*H12 -> 0
F13: =C13*E13 -> 0 | I13: =G13*H13 -> 0
F14: =C14*E14 -> 0 | I14: =G14*H14 -> 0
F15: =C15*E15 -> 0 | I15: =G15*H15 -> 0
F16: =C16*E16 -> 0 | I16: =G16*H16 -> 0
F17: =C17*E17 -> 0 | I17: =G17*H17 -> 0
F18: =C18*E18 -> 0 | I18: =G18*H18 -> 0
... F30: =C30*E30 -> 0 | I30: =G30*H30 -> 0
C31: MATERIAL TOTAL: | F31: =SUM(F6:F30) -> 0 | G31: LABOR TOTAL: | I31: =SUM(I6:I30) -> 0
A32: TOTAL TI MATERIAL AND LABOR: | I32: =SUM(I31,F31) -> 0
A33: SHELL Cost Estimate for Division 26.2 (examples: lighting fixtures, wall switches, motion switches)
A34: DESCRIPTION | C34: MATERIAL | G34: LABOR
C35: QUANTITY | D35: UNIT | E35: COST | F35: TOTAL | G35: HOURS | H35: Labor Rate | I35: TOTAL
C36: 1 | E36: 0 | F36: =C36*E36 -> 0 | G36: 1 | H36: 0 | I36: =G36*H36 -> 0
F37: =C37*E37 -> 0 | I37: =G37*H37 -> 0
F38: =C38*E38 -> 0 | I38: =G38*H38 -> 0
F39: =C39*E39 -> 0 | I39: =G39*H39 -> 0
F40: =C40*E40 -> 0 | I40: =G40*H40 -> 0
F41: =C41*E41 -> 0 | I41: =G41*H41 -> 0
F42: =C42*E42 -> 0 | I42: =G42*H42 -> 0
F43: =C43*E43 -> 0 | I43: =G43*H43 -> 0
F44: =C44*E44 -> 0 | I44: =G44*H44 -> 0
F45: =C45*E45 -> 0 | I45: =G45*H45 -> 0
F46: =C46*E46 -> 0 | I46: =G46*H46 -> 0
F47: =C47*E47 -> 0 | I47: =G47*H47 -> 0
F48: =C48*E48 -> 0 | I48: =G48*H48 -> 0
C49: MATERIAL TOTAL: | F49: =SUM(F36:F48) -> 0 | G49: LABOR TOTAL: | I49: =SUM(I36:I48) -> 0
A50: TOTAL SHELL MATERIAL AND LABOR: | I50: =SUM(I49,F49) -> 0

Sheet 27
A1: DIVISION 27 - COMMUNICATIONS | G1: FOR: | I1: DATE PREPARED:
G2: =IF(INPUT!C3=0,"",INPUT!C3) -> RLP # 36C248-25-R-0110 – EXHIBIT K | I2: =IF(INPUT!C10=0,"",INPUT!C10)
A3: Tentant Improvement (TI) Cost Estimate for Division 27 (examples: Low Voltage cabling (CAT6, POE, Coax, HDMI, speaker), overhead speakers/intercom, sound-masking/white noise devices, jacks, punchdown, cover plates, cable trays/j-hooks, server racks (conduit & boxes see Div 26.1))
A4: DESCRIPTION | C4: MATERIAL | G4: LABOR
C5: QUANTITY | D5: UNIT | E5: COST | F5: TOTAL | G5: HOURS | H5: Labor Rate | I5: TOTAL
A6: Describe first item here | C6: 1 | D6: (ex: LF) | E6: 0 | F6: =C6*E6 -> 0 | G6: 1 | H6: 0 | I6: =G6*H6 -> 0
F7: =C7*E7 -> 0 | I7: =G7*H7 -> 0
F8: =C8*E8 -> 0 | I8: =G8*H8 -> 0
F9: =C9*E9 -> 0 | I9: =G9*H9 -> 0
F10: =C10*E10 -> 0 | I10: =G10*H10 -> 0
F11: =C11*E11 -> 0 | I11: =G11*H11 -> 0
F12: =C12*E12 -> 0 | I12: =G12*H12 -> 0
F13: =C13*E13 -> 0 | I13: =G13*H13 -> 0
F14: =C14*E14 -> 0 | I14: =G14*H14 -> 0
F15: =C15*E15 -> 0 | I15: =G15*H15 -> 0
F16: =C16*E16 -> 0 | I16: =G16*H16 -> 0
F17: =C17*E17 -> 0 | I17: =G17*H17 -> 0
F18: =C18*E18 -> 0 | I18: =G18*H18 -> 0
... F30: =C30*E30 -> 0 | I30: =G30*H30 -> 0
C31: MATERIAL TOTAL: | F31: =SUM(F6:F30) -> 0 | G31: LABOR TOTAL: | I31: =SUM(I6:I30) -> 0
A32: TOTAL TI MATERIAL AND LABOR: | I32: =SUM(I31,F31) -> 0
A33: SHELL Cost Estimate for Division 27
A34: DESCRIPTION | C34: MATERIAL | G34: LABOR
C35: QUANTITY | D35: UNIT | E35: COST | F35: TOTAL | G35: HOURS | H35: Labor Rate | I35: TOTAL
C36: 1 | E36: 0 | F36: =C36*E36 -> 0 | G36: 1 | H36: 0 | I36: =G36*H36 -> 0
F37: =C37*E37 -> 0 | I37: =G37*H37 -> 0
F38: =C38*E38 -> 0 | I38: =G38*H38 -> 0
F39: =C39*E39 -> 0 | I39: =G39*H39 -> 0
F40: =C40*E40 -> 0 | I40: =G40*H40 -> 0
F41: =C41*E41 -> 0 | I41: =G41*H41 -> 0
F42: =C42*E42 -> 0 | I42: =G42*H42 -> 0
F43: =C43*E43 -> 0 | I43: =G43*H43 -> 0
F44: =C44*E44 -> 0 | I44: =G44*H44 -> 0
F45: =C45*E45 -> 0 | I45: =G45*H45 -> 0
F46: =C46*E46 -> 0 | I46: =G46*H46 -> 0
F47: =C47*E47 -> 0 | I47: =G47*H47 -> 0
F48: =C48*E48 -> 0 | I48: =G48*H48 -> 0
C49: MATERIAL TOTAL: | F49: =SUM(F36:F48) -> 0 | G49: LABOR TOTAL: | I49: =SUM(I36:I48) -> 0
A50: TOTAL SHELL MATERIAL AND LABOR: | I50: =SUM(I49,F49) -> 0

Sheet 28.1
A1: DIVISION 28.1 - ELECTRONIC SAFETY | G1: FOR: | I1: DATE PREPARED:
G2: =IF(INPUT!C3=0,"",INPUT!C3) -> RLP # 36C248-25-R-0110 – EXHIBIT K | I2: =IF(INPUT!C10=0,"",INPUT!C10)
A3: Tentant Improvement (TI) Cost Estimate for Division 28.1 (examples: Fire Alarm Only: wire, devices, smokes, heats, CO2, exit signs, addressing & testing)
A4: DESCRIPTION | C4: MATERIAL | G4: LABOR
C5: QUANTITY | D5: UNIT | E5: COST | F5: TOTAL | G5: HOURS | H5: Labor Rate | I5: TOTAL
A6: Describe first item here | C6: 1 | D6: (ex: LF) | E6: 0 | F6: =C6*E6 -> 0 | G6: 1 | H6: 0 | I6: =G6*H6 -> 0
F7: =C7*E7 -> 0 | I7: =G7*H7 -> 0
F8: =C8*E8 -> 0 | I8: =G8*H8 -> 0
F9: =C9*E9 -> 0 | I9: =G9*H9 -> 0
F10: =C10*E10 -> 0 | I10: =G10*H10 -> 0
F11: =C11*E11 -> 0 | I11: =G11*H11 -> 0
F12: =C12*E12 -> 0 | I12: =G12*H12 -> 0
F13: =C13*E13 -> 0 | I13: =G13*H13 -> 0
F14: =C14*E14 -> 0 | I14: =G14*H14 -> 0
F15: =C15*E15 -> 0 | I15: =G15*H15 -> 0
F16: =C16*E16 -> 0 | I16: =G16*H16 -> 0
F17: =C17*E17 -> 0 | I17: =G17*H17 -> 0
F18: =C18*E18 -> 0 | I18: =G18*H18 -> 0
... F30: =C30*E30 -> 0 | I30: =G30*H30 -> 0
C31: MATERIAL TOTAL: | F31: =SUM(F6:F30) -> 0 | G31: LABOR TOTAL: | I31: =SUM(I6:I30) -> 0
A32: TOTAL TI MATERIAL AND LABOR: | I32: =SUM(I31,F31) -> 0
A33: SHELL Cost Estimate for Division 28.1
A34: DESCRIPTION | C34: MATERIAL | G34: LABOR
C35: QUANTITY | D35: UNIT | E35: COST | F35: TOTAL | G35: HOURS | H35: Labor Rate | I35: TOTAL
C36: 1 | E36: 0 | F36: =C36*E36 -> 0 | G36: 1 | H36: 0 | I36: =G36*H36 -> 0
F37: =C37*E37 -> 0 | I37: =G37*H37 -> 0
F38: =C38*E38 -> 0 | I38: =G38*H38 -> 0
F39: =C39*E39 -> 0 | I39: =G39*H39 -> 0
F40: =C40*E40 -> 0 | I40: =G40*H40 -> 0
F41: =C41*E41 -> 0 | I41: =G41*H41 -> 0
F42: =C42*E42 -> 0 | I42: =G42*H42 -> 0
F43: =C43*E43 -> 0 | I43: =G43*H43 -> 0
F44: =C44*E44 -> 0 | I44: =G44*H44 -> 0
F45: =C45*E45 -> 0 | I45: =G45*H45 -> 0
F46: =C46*E46 -> 0 | I46: =G46*H46 -> 0
F47: =C47*E47 -> 0 | I47: =G47*H47 -> 0
F48: =C48*E48 -> 0 | I48: =G48*H48 -> 0
C49: MATERIAL TOTAL: | F49: =SUM(F36:F48) -> 0 | G49: LABOR TOTAL: | I49: =SUM(I36:I48) -> 0
A50: TOTAL SHELL MATERIAL AND LABOR: | I50: =SUM(I49,F49) -> 0

Sheet 28.2
A1: DIVISION 28.2 - ELECTRONIC SECURITY | G1: FOR: | I1: DATE PREPARED:
G2: =IF(INPUT!C3=0,"",INPUT!C3) -> RLP # 36C248-25-R-0110 – EXHIBIT K | I2: =IF(INPUT!C10=0,"",INPUT!C10)
A3: Tentant Improvement (TI) Cost Estimate for Division 28.2 (examples: duress, IDS, motion, video surveillance systems, CCTV, security scanning, glass break, alarm devices) SHOULD NOT include items required/itemized as BSAC on a Security Unit Price List, provided separately, or the BSAC tab on this form. SHOULD include items labeled TI on a Security Unit Price List.
A4: DESCRIPTION | C4: MATERIAL | G4: LABOR
C5: QUANTITY | D5: UNIT | E5: COST | F5: TOTAL | G5: HOURS | H5: Labor Rate | I5: TOTAL
A6: Describe first item here | C6: 1 | D6: (ex: LF) | E6: 0 | F6: =C6*E6 -> 0 | G6: 1 | H6: 0 | I6: =G6*H6 -> 0
F7: =C7*E7 -> 0 | I7: =G7*H7 -> 0
F8: =C8*E8 -> 0 | I8: =G8*H8 -> 0
F9: =C9*E9 -> 0 | I9: =G9*H9 -> 0
F10: =C10*E10 -> 0 | I10: =G10*H10 -> 0
F11: =C11*E11 -> 0 | I11: =G11*H11 -> 0
F12: =C12*E12 -> 0 | I12: =G12*H12 -> 0
F13: =C13*E13 -> 0 | I13: =G13*H13 -> 0
F14: =C14*E14 -> 0 | I14: =G14*H14 -> 0
F15: =C15*E15 -> 0 | I15: =G15*H15 -> 0
F16: =C16*E16 -> 0 | I16: =G16*H16 -> 0
F17: =C17*E17 -> 0 | I17: =G17*H17 -> 0
F18: =C18*E18 -> 0 | I18: =G18*H18 -> 0
... F30: =C30*E30 -> 0 | I30: =G30*H30 -> 0
C31: MATERIAL TOTAL: | F31: =SUM(F6:F30) -> 0 | G31: LABOR TOTAL: | I31: =SUM(I6:I30) -> 0
A32: TOTAL TI MATERIAL AND LABOR: | I32: =SUM(I31,F31) -> 0
A33: SHELL Cost Estimate for Division 28.2 SHOULD NOT include items required/itemized as BSAC on a Security Unit Price List, provided separately if necessary. SHOULD include items labeled SHELL on a Security Unit Price List.
A34: DESCRIPTION | C34: MATERIAL | G34: LABOR
C35: QUANTITY | D35: UNIT | E35: COST | F35: TOTAL | G35: HOURS | H35: Labor Rate | I35: TOTAL
C36: 1 | E36: 0 | F36: =C36*E36 -> 0 | G36: 1 | H36: 0 | I36: =G36*H36 -> 0
